Workbook

Sheet Resumen
A1: Estado de avance de la digitalización de los censos históricos (1813–1982)
A2: Generado el 21-10-2026 con herramientas/resumen_avance.py. Conteos y niveles: fórmulas sobre las hojas Catálogo y Cifras. Columnas en azul: escritas a mano. Ver la hoja Notas.
A4: Censo | B4: Publicaciones | C4: Páginas del PDF | D4: Entradas en el catálogo | E4: Cuadros | F4: Bloques | G4: Textos | H4: Página del PDF verificada | I4: Página del PDF estimada | J4: Página sin ubicar o ausente | K4: Cuadros transcritos de la publicación | L4: Cifras digitalizadas del censo | M4: Total: transcrito | N4: Total: en los PDF | O4: Área: transcrito | P4: Área: en los PDF | Q4: Área × sexo: transcrito | R4: Área × sexo: en los PDF | S4: Sexo × edad: transcrito | T4: Sexo × edad: en los PDF | U4: Cifras inconsistentes anotadas | V4: Estado | W4: Pendiente / próximo paso | X4: Observaciones
A5: 1813 | B5: pub_1813 | C5: 263 | D5: =COUNTIFS(Catálogo!$B$2:$B$648,$A5) -> 31 | E5: =COUNTIFS(Catálogo!$B$2:$B$648,$A5,Catálogo!$F$2:$F$648,"cuadro") -> 15 | F5: =COUNTIFS(Catálogo!$B$2:$B$648,$A5,Catálogo!$F$2:$F$648,"bloque") -> 14 | G5: =COUNTIFS(Catálogo!$B$2:$B$648,$A5,Catálogo!$F$2:$F$648,"texto") -> 2 | H5: =COUNTIFS(Catálogo!$B$2:$B$648,$A5,Catálogo!$I$2:$I$648,"verificada") -> 31 | I5: =COUNTIFS(Catálogo!$B$2:$B$648,$A5,Catálogo!$I$2:$I$648,"estimada") -> 0 | J5: =COUNTIFS(Catálogo!$B$2:$B$648,$A5,Catálogo!$I$2:$I$648,"desconocida")+COUNTIFS(Catálogo!$B$2:$B$648,$A5,Catálogo!$I$2:$I$648,"ausente") -> 0 | K5: =COUNTIFS(Catálogo!$B$2:$B$648,$A5,Catálogo!$O$2:$O$648,"transcrito") -> 14 | L5: =SUMIFS(Cifras!$H$2:$H$399,Cifras!$A$2:$A$399,$A5) -> 596 | M5: =IF(COUNTIFS(Cifras!$A$2:$A$399,$A5,Cifras!$D$2:$D$399,"distrito")>0,"Distrito",IF(COUNTIFS(Cifras!$A$2:$A$399,$A5,Cifras!$D$2:$D$399,"comuna")>0,"Comuna",IF(COUNTIFS(Cifras!$A$2:$A$399,$A5,Cifras!$D$2:$D$399,"partido")>0,"Partido",IF(COUNTIFS(Cifras!$A$2:$A$399,$A5,Cifras!$D$2:$D$399,"departamento")>0,"Departamento",IF(COUNTIFS(Cifras!$A$2:$A$399,$A5,Cifras!$D$2:$D$399,"provincia")>0,"Provincia",IF(COUNTIFS(Cifras!$A$2:$A$399,$A5,Cifras!$D$2:$D$399,"region")>0,"Región",IF(COUNTIFS(Cifras!$A$2:$A$399,$A5,Cifras!$D$2:$D$399,"pais")>0,"País","—"))))))) -> Distrito | N5: =IF(IFERROR(MATCH(TRUE,COUNTIFS(Catálogo!$J$2:$J$648,"*"&$A5&"*",Catálogo!$I$2:$I$648,"<>ausente",Catálogo!$M$2:$M$648,"completa",Catálogo!$Q$2:$Q$648,{1,2,3,4,5,6,7,8,9})>0,0),0)>0,INDEX(Niveles!$C$2:$C$10,IFERROR(MATCH(TRUE,COUNTIFS(Catálogo!$J$2:$J$648,"*"&$A5&"*",Catálogo!$I$2:$I$648,"<>ausente",Catálogo!$M$2:$M$648,"completa",Catálogo!$Q$2:$Q$648,{1,2,3,4,5,6,7,8,9})>0,0),0))&IF(AND(IFERROR(MATCH(TRUE,COUNTIFS(Catálogo!$J$2:$J$648,"*"&$A5&"*",Catálogo!$I$2:$I$648,"<>ausente",Catálogo!$M$2:$M$648,"parcial",Catálogo!$Q$2:$Q$648,{1,2,3,4,5,6,7,8,9})>0,0),0)>0,IFERROR(MATCH(TRUE,COUNTIFS(Catálogo!$J$2:$J$648,"*"&$A5&"*",Catálogo!$I$2:$I$648,"<>ausente",Catálogo!$M$2:$M$648,"parcial",Catálogo!$Q$2:$Q$648,{1,2,3,4,5,6,7,8,9})>0,0),0)<IFERROR(MATCH(TRUE,COUNTIFS(Catálogo!$J$2:$J$648,"*"&$A5&"*",Catálogo!$I$2:$I$648,"<>ausente",Catálogo!$M$2:$M$648,"completa",Catálogo!$Q$2:$Q$648,{1,2,3,4,5,6,7,8,9})>0,0),0)),"; "&LOWER(INDEX(Niveles!$C$2:$C$10,IFERROR(MATCH(TRUE,COUNTIFS(Catálogo!$J$2:$J$648,"*"&$A5&"*",Catálogo!$I$2:$I$648,"<>ausente",Catálogo!$M$2:$M$648,"parcial",Catálogo!$Q$2:$Q$648,{1,2,3,4,5,6,7,8,9})>0,0),0)))&" (parcial)",""),IF(IFERROR(MATCH(TRUE,COUNTIFS(Catálogo!$J$2:$J$648,"*"&$A5&"*",Catálogo!$I$2:$I$648,"<>ausente",Catálogo!$M$2:$M$648,"parcial",Catálogo!$Q$2:$Q$648,{1,2,3,4,5,6,7,8,9})>0,0),0)>0,INDEX(Niveles!$C$2:$C$10,IFERROR(MATCH(TRUE,COUNTIFS(Catálogo!$J$2:$J$648,"*"&$A5&"*",Catálogo!$I$2:$I$648,"<>ausente",Catálogo!$M$2:$M$648,"parcial",Catálogo!$Q$2:$Q$648,{1,2,3,4,5,6,7,8,9})>0,0),0))&" (parcial)","—")) -> Distrito (parcial) | O5: =IF(COUNTIFS(Cifras!$A$2:$A$399,$A5,Cifras!$E$2:$E$399,"Sí",Cifras!$D$2:$D$399,"distrito")>0,"Distrito",IF(COUNTIFS(Cifras!$A$2:$A$399,$A5,Cifras!$E$2:$E$399,"Sí",Cifras!$D$2:$D$399,"comuna")>0,"Comuna",IF(COUNTIFS(Cifras!$A$2:$A$399,$A5,Cifras!$E$2:$E$399,"Sí",Cifras!$D$2:$D$399,"partido")>0,"Partido",IF(COUNTIFS(Cifras!$A$2:$A$399,$A5,Cifras!$E$2:$E$399,"Sí",Cifras!$D$2:$D$399,"departamento")>0,"Departamento",IF(COUNTIFS(Cifras!$A$2:$A$399,$A5,Cifras!$E$2:$E$399,"Sí",Cifras!$D$2:$D$399,"provincia")>0,"Provincia",IF(COUNTIFS(Cifras!$A$2:$A$399,$A5,Cifras!$E$2:$E$399,"Sí",Cifras!$D$2:$D$399,"region")>0,"Región",IF(COUNTIFS(Cifras!$A$2:$A$399,$A5,Cifras!$E$2:$E$399,"Sí",Cifras!$D$2:$D$399,"pais")>0,"País","—"))))))) -> — | P5: =IF(IFERROR(MATCH(TRUE,COUNTIFS(Catálogo!$J$2:$J$648,"*"&$A5&"*",Catálogo!$I$2:$I$648,"<>ausente",Catálogo!$M$2:$M$648,"completa",Catálogo!$L$2:$L$648,"*area*",Catálogo!$Q$2:$Q$648,{1,2,3,4,5,6,7,8,9})>0,0),0)>0,INDEX(Niveles!$C$2:$C$10,IFERROR(MATCH(TRUE,COUNTIFS(Catálogo!$J$2:$J$648,"*"&$A5&"*",Catálogo!$I$2:$I$648,"<>ausente",Catálogo!$M$2:$M$648,"completa",Catálogo!$L$2:$L$648,"*area*",Catálogo!$Q$2:$Q$648,{1,2,3,4,5,6,7,8,9})>0,0),0))&IF(AND(IFERROR(MATCH(TRUE,COUNTIFS(Catálogo!$J$2:$J$648,"*"&$A5&"*",Catálogo!$I$2:$I$648,"<>ausente",Catálogo!$M$2:$M$648,"parcial",Catálogo!$L$2:$L$648,"*area*",Catálogo!$Q$2:$Q$648,{1,2,3,4,5,6,7,8,9})>0,0),0)>0,IFERROR(MATCH(TRUE,COUNTIFS(Catálogo!$J$2:$J$648,"*"&$A5&"*",Catálogo!$I$2:$I$648,"<>ausente",Catálogo!$M$2:$M$648,"parcial",Catálogo!$L$2:$L$648,"*area*",Catálogo!$Q$2:$Q$648,{1,2,3,4,5,6,7,8,9})>0,0),0)<IFERROR(MATCH(TRUE,COUNTIFS(Catálogo!$J$2:$J$648,"*"&$A5&"*",Catálogo!$I$2:$I$648,"<>ausente",Catálogo!$M$2:$M$648,"completa",Catálogo!$L$2:$L$648,"*area*",Catálogo!$Q$2:$Q$648,{1,2,3,4,5,6,7,8,9})>0,0),0)),"; "&LOWER(INDEX(Niveles!$C$2:$C$10,IFERROR(MATCH(TRUE,COUNTIFS(Catálogo!$J$2:$J$648,"*"&$A5&"*",Catálogo!$I$2:$I$648,"<>ausente",Catálogo!$M$2:$M$648,"parcial",Catálogo!$L$2:$L$648,"*area*",Catálogo!$Q$2:$Q$648,{1,2,3,4,5,6,7,8,9})>0,0),0)))&" (parcial)",""),IF(IFERROR(MATCH(TRUE,COUNTIFS(Catálogo!$J$2:$J$648,"*"&$A5&"*",Catálogo!$I$2:$I$648,"<>ausente",Catálogo!$M$2:$M$648,"parcial",Catálogo!$L$2:$L$648,"*area*",Catálogo!$Q$2:$Q$648,{1,2,3,4,5,6,7,8,9})>0,0),0)>0,INDEX(Niveles!$C$2:$C$10,IFERROR(MATCH(TRUE,COUNTIFS(Catálogo!$J$2:$J$648,"*"&$A5&"*",Catálogo!$I$2:$I$648,"<>ausente",Catálogo!$M$2:$M$648,"parcial",Catálogo!$L$2:$L$648,"*area*",Catálogo!$Q$2:$Q$648,{1,2,3,4,5,6,7,8,9})>0,0),0))&" (parcial)","—")) -> — | Q5: =IF(COUNTIFS(Cifras!$A$2:$A$399,$A5,Cifras!$E$2:$E$399,"Sí",Cifras!$F$2:$F$399,"Sí",Cifras!$D$2:$D$399,"distrito")>0,"Distrito",IF(COUNTIFS(Cifras!$A$2:$A$399,$A5,Cifras!$E$2:$E$399,"Sí",Cifras!$F$2:$F$399,"Sí",Cifras!$D$2:$D$399,"comuna")>0,"Comuna",IF(COUNTIFS(Cifras!$A$2:$A$399,$A5,Cifras!$E$2:$E$399,"Sí",Cifras!$F$2:$F$399,"Sí",Cifras!$D$2:$D$399,"partido")>0,"Partido",IF(COUNTIFS(Cifras!$A$2:$A$399,$A5,Cifras!$E$2:$E$399,"Sí",Cifras!$F$2:$F$399,"Sí",Cifras!$D$2:$D$399,"departamento")>0,"Departamento",IF(COUNTIFS(Cifras!$A$2:$A$399,$A5,Cifras!$E$2:$E$399,"Sí",Cifras!$F$2:$F$399,"Sí",Cifras!$D$2:$D$399,"provincia")>0,"Provincia",IF(COUNTIFS(Cifras!$A$2:$A$399,$A5,Cifras!$E$2:$E$399,"Sí",Cifras!$F$2:$F$399,"Sí",Cifras!$D$2:$D$399,"region")>0,"Región",IF(COUNTIFS(Cifras!$A$2:$A$399,$A5,Cifras!$E$2:$E$399,"Sí",Cifras!$F$2:$F$399,"Sí",Cifras!$D$2:$D$399,"pais")>0,"País","—"))))))) -> — | R5: =IF(IFERROR(MATCH(TRUE,COUNTIFS(Catálogo!$J$2:$J$648,"*"&$A5&"*",Catálogo!$I$2:$I$648,"<>ausente",Catálogo!$M$2:$M$648,"completa",Catálogo!$L$2:$L$648,"*area*",Catálogo!$L$2:$L$648,"*sexo*",Catálogo!$Q$2:$Q$648,{1,2,3,4,5,6,7,8,9})>0,0),0)>0,INDEX(Niveles!$C$2:$C$10,IFERROR(MATCH(TRUE,COUNTIFS(Catálogo!$J$2:$J$648,"*"&$A5&"*",Catálogo!$I$2:$I$648,"<>ausente",Catálogo!$M$2:$M$648,"completa",Catálogo!$L$2:$L$648,"*area*",Catálogo!$L$2:$L$648,"*sexo*",Catálogo!$Q$2:$Q$648,{1,2,3,4,5,6,7,8,9})>0,0),0))&IF(AND(IFERROR(MATCH(TRUE,COUNTIFS(Catálogo!$J$2:$J$648,"*"&$A5&"*",Catálogo!$I$2:$I$648,"<>ausente",Catálogo!$M$2:$M$648,"parcial",Catálogo!$L$2:$L$648,"*area*",Catálogo!$L$2:$L$648,"*sexo*",Catálogo!$Q$2:$Q$648,{1,2,3,4,5,6,7,8,9})>0,0),0)>0,IFERROR(MATCH(TRUE,COUNTIFS(Catálogo!$J$2:$J$648,"*"&$A5&"*",Catálogo!$I$2:$I$648,"<>ausente",Catálogo!$M$2:$M$648,"parcial",Catálogo!$L$2:$L$648,"*area*",Catálogo!$L$2:$L$648,"*sexo*",Catálogo!$Q$2:$Q$648,{1,2,3,4,5,6,7,8,9})>0,0),0)<IFERROR(MATCH(TRUE,COUNTIFS(Catálogo!$J$2:$J$648,"*"&$A5&"*",Catálogo!$I$2:$I$648,"<>ausente",Catálogo!$M$2:$M$648,"completa",Catálogo!$L$2:$L$648,"*area*",Catálogo!$L$2:$L$648,"*sexo*",Catálogo!$Q$2:$Q$648,{1,2,3,4,5,6,7,8,9})>0,0),0)),"; "&LOWER(INDEX(Niveles!$C$2:$C$10,IFERROR(MATCH(TRUE,COUNTIFS(Catálogo!$J$2:$J$648,"*"&$A5&"*",Catálogo!$I$2:$I$648,"<>ausente",Catálogo!$M$2:$M$648,"parcial",Catálogo!$L$2:$L$648,"*area*",Catálogo!$L$2:$L$648,"*sexo*",Catálogo!$Q$2:$Q$648,{1,2,3,4,5,6,7,8,9})>0,0),0)))&" (parcial)",""),IF(IFERROR(MATCH(TRUE,COUNTIFS(Catálogo!$J$2:$J$648,"*"&$A5&"*",Catálogo!$I$2:$I$648,"<>ausente",Catálogo!$M$2:$M$648,"parcial",Catálogo!$L$2:$L$648,"*area*",Catálogo!$L$2:$L$648,"*sexo*",Catálogo!$Q$2:$Q$648,{1,2,3,4,5,6,7,8,9})>0,0),0)>0,INDEX(Niveles!$C$2:$C$10,IFERROR(MATCH(TRUE,COUNTIFS(Catálogo!$J$2:$J$648,"*"&$A5&"*",Catálogo!$I$2:$I$648,"<>ausente",Catálogo!$M$2:$M$648,"parcial",Catálogo!$L$2:$L$648,"*area*",Catálogo!$L$2:$L$648,"*sexo*",Catálogo!$Q$2:$Q$648,{1,2,3,4,5,6,7,8,9})>0,0),0))&" (parcial)","—")) -> — | S5: =IF(COUNTIFS(Cifras!$A$2:$A$399,$A5,Cifras!$F$2:$F$399,"Sí",Cifras!$G$2:$G$399,"Sí",Cifras!$D$2:$D$399,"distrito")>0,"Distrito",IF(COUNTIFS(Cifras!$A$2:$A$399,$A5,Cifras!$F$2:$F$399,"Sí",Cifras!$G$2:$G$399,"Sí",Cifras!$D$2:$D$399,"comuna")>0,"Comuna",IF(COUNTIFS(Cifras!$A$2:$A$399,$A5,Cifras!$F$2:$F$399,"Sí",Cifras!$G$2:$G$399,"Sí",Cifras!$D$2:$D$399,"partido")>0,"Partido",IF(COUNTIFS(Cifras!$A$2:$A$399,$A5,Cifras!$F$2:$F$399,"Sí",Cifras!$G$2:$G$399,"Sí",Cifras!$D$2:$D$399,"departamento")>0,"Departamento",IF(COUNTIFS(Cifras!$A$2:$A$399,$A5,Cifras!$F$2:$F$399,"Sí",Cifras!$G$2:$G$399,"Sí",Cifras!$D$2:$D$399,"provincia")>0,"Provincia",IF(COUNTIFS(Cifras!$A$2:$A$399,$A5,Cifras!$F$2:$F$399,"Sí",Cifras!$G$2:$G$399,"Sí",Cifras!$D$2:$D$399,"region")>0,"Región",IF(COUNTIFS(Cifras!$A$2:$A$399,$A5,Cifras!$F$2:$F$399,"Sí",Cifras!$G$2:$G$399,"Sí",Cifras!$D$2:$D$399,"pais")>0,"País","—"))))))) -> Partido | T5: =IF(IFERROR(MATCH(TRUE,COUNTIFS(Catálogo!$J$2:$J$648,"*"&$A5&"*",Catálogo!$I$2:$I$648,"<>ausente",Catálogo!$M$2:$M$648,"completa",Catálogo!$L$2:$L$648,"*sexo*",Catálogo!$L$2:$L$648,"*edad*",Catálogo!$Q$2:$Q$648,{1,2,3,4,5,6,7,8,9})>0,0),0)>0,INDEX(Niveles!$C$2:$C$10,IFERROR(MATCH(TRUE,COUNTIFS(Catálogo!$J$2:$J$648,"*"&$A5&"*",Catálogo!$I$2:$I$648,"<>ausente",Catálogo!$M$2:$M$648,"completa",Catálogo!$L$2:$L$648,"*sexo*",Catálogo!$L$2:$L$648,"*edad*",Catálogo!$Q$2:$Q$648,{1,2,3,4,5,6,7,8,9})>0,0),0))&IF(AND(IFERROR(MATCH(TRUE,COUNTIFS(Catálogo!$J$2:$J$648,"*"&$A5&"*",Catálogo!$I$2:$I$648,"<>ausente",Catálogo!$M$2:$M$648,"parcial",Catálogo!$L$2:$L$648,"*sexo*",Catálogo!$L$2:$L$648,"*edad*",Catálogo!$Q$2:$Q$648,{1,2,3,4,5,6,7,8,9})>0,0),0)>0,IFERROR(MATCH(TRUE,COUNTIFS(Catálogo!$J$2:$J$648,"*"&$A5&"*",Catálogo!$I$2:$I$648,"<>ausente",Catálogo!$M$2:$M$648,"parcial",Catálogo!$L$2:$L$648,"*sexo*",Catálogo!$L$2:$L$648,"*edad*",Catálogo!$Q$2:$Q$648,{1,2,3,4,5,6,7,8,9})>0,0),0)<IFERROR(MATCH(TRUE,COUNTIFS(Catálogo!$J$2:$J$648,"*"&$A5&"*",Catálogo!$I$2:$I$648,"<>ausente",Catálogo!$M$2:$M$648,"completa",Catálogo!$L$2:$L$648,"*sexo*",Catálogo!$L$2:$L$648,"*edad*",Catálogo!$Q$2:$Q$648,{1,2,3,4,5,6,7,8,9})>0,0),0)),"; "&LOWER(INDEX(Niveles!$C$2:$C$10,IFERROR(MATCH(TRUE,COUNTIFS(Catálogo!$J$2:$J$648,"*"&$A5&"*",Catálogo!$I$2:$I$648,"<>ausente",Catálogo!$M$2:$M$648,"parcial",Catálogo!$L$2:$L$648,"*sexo*",Catálogo!$L$2:$L$648,"*edad*",Catálogo!$Q$2:$Q$648,{1,2,3,4,5,6,7,8,9})>0,0),0)))&" (parcial)",""),IF(IFERROR(MATCH(TRUE,COUNTIFS(Catálogo!$J$2:$J$648,"*"&$A5&"*",Catálogo!$I$2:$I$648,"<>ausente",Catálogo!$M$2:$M$648,"parcial",Catálogo!$L$2:$L$648,"*sexo*",Catálogo!$L$2:$L$648,"*edad*",Catálogo!$Q$2:$Q$648,{1,2,3,4,5,6,7,8,9})>0,0),0)>0,INDEX(Niveles!$C$2:$C$10,IFERROR(MATCH(TRUE,COUNTIFS(Catálogo!$J$2:$J$648,"*"&$A5&"*",Catálogo!$I$2:$I$648,"<>ausente",Catálogo!$M$2:$M$648,"parcial",Catálogo!$L$2:$L$648,"*sexo*",Catálogo!$L$2:$L$648,"*edad*",Catálogo!$Q$2:$Q$648,{1,2,3,4,5,6,7,8,9})>0,0),0))&" (parcial)","—")) -> Distrito (parcial) | U5: =SUMIFS(Cifras!$J$2:$J$399,Cifras!$A$2:$A$399,$A5) -> 0 | V5: Parcial | W5: Opcional: edades por distrito desde los «Censo de territorio» (bloques). Santiago no está en la edición; Concepción solo con matrículas de 1812. | X5: Partido × sexo × edad (5 tramos) y × estado civil, y distrito × sexo, de los 14 partidos de Copiapó a Talca (cobertura parcial del país). Totales validados con el estado civil; en 8 partidos las edades no suman el total y en 4 los distritos tampoco (impreso así).
A6: 1835 | B6: pub_1835 | C6: 117 | D6: =COUNTIFS(Catálogo!$B$2:$B$648,$A6) -> 15 | E6: =COUNTIFS(Catálogo!$B$2:$B$648,$A6,Catálogo!$F$2:$F$648,"cuadro") -> 10 | F6: =COUNTIFS(Catálogo!$B$2:$B$648,$A6,Catálogo!$F$2:$F$648,"bloque") -> 0 | G6: =COUNTIFS(Catálogo!$B$2:$B$648,$A6,Catálogo!$F$2:$F$648,"texto") -> 5 | H6: =COUNTIFS(Catálogo!$B$2:$B$648,$A6,Catálogo!$I$2:$I$648,"verificada") -> 1 | I6: =COUNTIFS(Catálogo!$B$2:$B$648,$A6,Catálogo!$I$2:$I$648,"estimada") -> 14 | J6: =COUNTIFS(Catálogo!$B$2:$B$648,$A6,Catálogo!$I$2:$I$648,"desconocida")+COUNTIFS(Catálogo!$B$2:$B$648,$A6,Catálogo!$I$2:$I$648,"ausente") -> 0 | K6: =COUNTIFS(Catálogo!$B$2:$B$648,$A6,Catálogo!$O$2:$O$648,"transcrito") -> 9 | L6: =SUMIFS(Cifras!$H$2:$H$399,Cifras!$A$2:$A$399,$A6) -> 430 | M6: =IF(COUNTIFS(Cifras!$A$2:$A$399,$A6,Cifras!$D$2:$D$399,"distrito")>0,"Distrito",IF(COUNTIFS(Cifras!$A$2:$A$399,$A6,Cifras!$D$2:$D$399,"comuna")>0,"Comuna",IF(COUNTIFS(Cifras!$A$2:$A$399,$A6,Cifras!$D$2:$D$399,"partido")>0,"Partido",IF(COUNTIFS(Cifras!$A$2:$A$399,$A6,Cifras!$D$2:$D$399,"departamento")>0,"Departamento",IF(COUNTIFS(Cifras!$A$2:$A$399,$A6,Cifras!$D$2:$D$399,"provincia")>0,"Provincia",IF(COUNTIFS(Cifras!$A$2:$A$399,$A6,Cifras!$D$2:$D$399,"region")>0,"Región",IF(COUNTIFS(Cifras!$A$2:$A$399,$A6,Cifras!$D$2:$D$399,"pais")>0,"País","—"))))))) -> Departamento | N6: =IF(IFERROR(MATCH(TRUE,COUNTIFS(Catálogo!$J$2:$J$648,"*"&$A6&"*",Catálogo!$I$2:$I$648,"<>ausente",Catálogo!$M$2:$M$648,"completa",Catálogo!$Q$2:$Q$648,{1,2,3,4,5,6,7,8,9})>0,0),0)>0,INDEX(Niveles!$C$2:$C$10,IFERROR(MATCH(TRUE,COUNTIFS(Catálogo!$J$2:$J$648,"*"&$A6&"*",Catálogo!$I$2:$I$648,"<>ausente",Catálogo!$M$2:$M$648,"completa",Catálogo!$Q$2:$Q$648,{1,2,3,4,5,6,7,8,9})>0,0),0))&IF(AND(IFERROR(MATCH(TRUE,COUNTIFS(Catálogo!$J$2:$J$648,"*"&$A6&"*",Catálogo!$I$2:$I$648,"<>ausente",Catálogo!$M$2:$M$648,"parcial",Catálogo!$Q$2:$Q$648,{1,2,3,4,5,6,7,8,9})>0,0),0)>0,IFERROR(MATCH(TRUE,COUNTIFS(Catálogo!$J$2:$J$648,"*"&$A6&"*",Catálogo!$I$2:$I$648,"<>ausente",Catálogo!$M$2:$M$648,"parcial",Catálogo!$Q$2:$Q$648,{1,2,3,4,5,6,7,8,9})>0,0),0)<IFERROR(MATCH(TRUE,COUNTIFS(Catálogo!$J$2:$J$648,"*"&$A6&"*",Catálogo!$I$2:$I$648,"<>ausente",Catálogo!$M$2:$M$648,"completa",Catálogo!$Q$2:$Q$648,{1,2,3,4,5,6,7,8,9})>0,0),0)),"; "&LOWER(INDEX(Niveles!$C$2:$C$10,IFERROR(MATCH(TRUE,COUNTIFS(Catálogo!$J$2:$J$648,"*"&$A6&"*",Catálogo!$I$2:$I$648,"<>ausente",Catálogo!$M$2:$M$648,"parcial",Catálogo!$Q$2:$Q$648,{1,2,3,4,5,6,7,8,9})>0,0),0)))&" (parcial)",""),IF(IFERROR(MATCH(TRUE,COUNTIFS(Catálogo!$J$2:$J$648,"*"&$A6&"*",Catálogo!$I$2:$I$648,"<>ausente",Catálogo!$M$2:$M$648,"parcial",Catálogo!$Q$2:$Q$648,{1,2,3,4,5,6,7,8,9})>0,0),0)>0,INDEX(Niveles!$C$2:$C$10,IFERROR(MATCH(TRUE,COUNTIFS(Catálogo!$J$2:$J$648,"*"&$A6&"*",Catálogo!$I$2:$I$648,"<>ausente",Catálogo!$M$2:$M$648,"parcial",Catálogo!$Q$2:$Q$648,{1,2,3,4,5,6,7,8,9})>0,0),0))&" (parcial)","—")) -> Departamento | O6: =IF(COUNTIFS(Cifras!$A$2:$A$399,$A6,Cifras!$E$2:$E$399,"Sí",Cifras!$D$2:$D$399,"distrito")>0,"Distrito",IF(COUNTIFS(Cifras!$A$2:$A$399,$A6,Cifras!$E$2:$E$399,"Sí",Cifras!$D$2:$D$399,"comuna")>0,"Comuna",IF(COUNTIFS(Cifras!$A$2:$A$399,$A6,Cifras!$E$2:$E$399,"Sí",Cifras!$D$2:$D$399,"partido")>0,"Partido",IF(COUNTIFS(Cifras!$A$2:$A$399,$A6,Cifras!$E$2:$E$399,"Sí",Cifras!$D$2:$D$399,"departamento")>0,"Departamento",IF(COUNTIFS(Cifras!$A$2:$A$399,$A6,Cifras!$E$2:$E$399,"Sí",Cifras!$D$2:$D$399,"provincia")>0,"Provincia",IF(COUNTIFS(Cifras!$A$2:$A$399,$A6,Cifras!$E$2:$E$399,"Sí",Cifras!$D$2:$D$399,"region")>0,"Región",IF(COUNTIFS(Cifras!$A$2:$A$399,$A6,Cifras!$E$2:$E$399,"Sí",Cifras!$D$2:$D$399,"pais")>0,"País","—"))))))) -> — | P6: =IF(IFERROR(MATCH(TRUE,COUNTIFS(Catálogo!$J$2:$J$648,"*"&$A6&"*",Catálogo!$I$2:$I$648,"<>ausente",Catálogo!$M$2:$M$648,"completa",Catálogo!$L$2:$L$648,"*area*",Catálogo!$Q$2:$Q$648,{1,2,3,4,5,6,7,8,9})>0,0),0)>0,INDEX(Niveles!$C$2:$C$10,IFERROR(MATCH(TRUE,COUNTIFS(Catálogo!$J$2:$J$648,"*"&$A6&"*",Catálogo!$I$2:$I$648,"<>ausente",Catálogo!$M$2:$M$648,"completa",Catálogo!$L$2:$L$648,"*area*",Catálogo!$Q$2:$Q$648,{1,2,3,4,5,6,7,8,9})>0,0),0))&IF(AND(IFERROR(MATCH(TRUE,COUNTIFS(Catálogo!$J$2:$J$648,"*"&$A6&"*",Catálogo!$I$2:$I$648,"<>ausente",Catálogo!$M$2:$M$648,"parcial",Catálogo!$L$2:$L$648,"*area*",Catálogo!$Q$2:$Q$648,{1,2,3,4,5,6,7,8,9})>0,0),0)>0,IFERROR(MATCH(TRUE,COUNTIFS(Catálogo!$J$2:$J$648,"*"&$A6&"*",Catálogo!$I$2:$I$648,"<>ausente",Catálogo!$M$2:$M$648,"parcial",Catálogo!$L$2:$L$648,"*area*",Catálogo!$Q$2:$Q$648,{1,2,3,4,5,6,7,8,9})>0,0),0)<IFERROR(MATCH(TRUE,COUNTIFS(Catálogo!$J$2:$J$648,"*"&$A6&"*",Catálogo!$I$2:$I$648,"<>ausente",Catálogo!$M$2:$M$648,"completa",Catálogo!$L$2:$L$648,"*area*",Catálogo!$Q$2:$Q$648,{1,2,3,4,5,6,7,8,9})>0,0),0)),"; "&LOWER(INDEX(Niveles!$C$2:$C$10,IFERROR(MATCH(TRUE,COUNTIFS(Catálogo!$J$2:$J$648,"*"&$A6&"*",Catálogo!$I$2:$I$648,"<>ausente",Catálogo!$M$2:$M$648,"parcial",Catálogo!$L$2:$L$648,"*area*",Catálogo!$Q$2:$Q$648,{1,2,3,4,5,6,7,8,9})>0,0),0)))&" (parcial)",""),IF(IFERROR(MATCH(TRUE,COUNTIFS(Catálogo!$J$2:$J$648,"*"&$A6&"*",Catálogo!$I$2:$I$648,"<>ausente",Catálogo!$M$2:$M$648,"parcial",Catálogo!$L$2:$L$648,"*area*",Catálogo!$Q$2:$Q$648,{1,2,3,4,5,6,7,8,9})>0,0),0)>0,INDEX(Niveles!$C$2:$C$10,IFERROR(MATCH(TRUE,COUNTIFS(Catálogo!$J$2:$J$648,"*"&$A6&"*",Catálogo!$I$2:$I$648,"<>ausente",Catálogo!$M$2:$M$648,"parcial",Catálogo!$L$2:$L$648,"*area*",Catálogo!$Q$2:$Q$648,{1,2,3,4,5,6,7,8,9})>0,0),0))&" (parcial)","—")) -> — | Q6: =IF(COUNTIFS(Cifras!$A$2:$A$399,$A6,Cifras!$E$2:$E$399,"Sí",Cifras!$F$2:$F$399,"Sí",Cifras!$D$2:$D$399,"distrito")>0,"Distrito",IF(COUNTIFS(Cifras!$A$2:$A$399,$A6,Cifras!$E$2:$E$399,"Sí",Cifras!$F$2:$F$399,"Sí",Cifras!$D$2:$D$399,"comuna")>0,"Comuna",IF(COUNTIFS(Cifras!$A$2:$A$399,$A6,Cifras!$E$2:$E$399,"Sí",Cifras!$F$2:$F$399,"Sí",Cifras!$D$2:$D$399,"partido")>0,"Partido",IF(COUNTIFS(Cifras!$A$2:$A$399,$A6,Cifras!$E$2:$E$399,"Sí",Cifras!$F$2:$F$399,"Sí",Cifras!$D$2:$D$399,"departamento")>0,"Departamento",IF(COUNTIFS(Cifras!$A$2:$A$399,$A6,Cifras!$E$2:$E$399,"Sí",Cifras!$F$2:$F$399,"Sí",Cifras!$D$2:$D$399,"provincia")>0,"Provincia",IF(COUNTIFS(Cifras!$A$2:$A$399,$A6,Cifras!$E$2:$E$399,"Sí",Cifras!$F$2:$F$399,"Sí",Cifras!$D$2:$D$399,"region")>0,"Región",IF(COUNTIFS(Cifras!$A$2:$A$399,$A6,Cifras!$E$2:$E$399,"Sí",Cifras!$F$2:$F$399,"Sí",Cifras!$D$2:$D$399,"pais")>0,"País","—"))))))) -> — | R6: =IF(IFERROR(MATCH(TRUE,COUNTIFS(Catálogo!$J$2:$J$648,"*"&$A6&"*",Catálogo!$I$2:$I$648,"<>ausente",Catálogo!$M$2:$M$648,"completa",Catálogo!$L$2:$L$648,"*area*",Catálogo!$L$2:$L$648,"*sexo*",Catálogo!$Q$2:$Q$648,{1,2,3,4,5,6,7,8,9})>0,0),0)>0,INDEX(Niveles!$C$2:$C$10,IFERROR(MATCH(TRUE,COUNTIFS(Catálogo!$J$2:$J$648,"*"&$A6&"*",Catálogo!$I$2:$I$648,"<>ausente",Catálogo!$M$2:$M$648,"completa",Catálogo!$L$2:$L$648,"*area*",Catálogo!$L$2:$L$648,"*sexo*",Catálogo!$Q$2:$Q$648,{1,2,3,4,5,6,7,8,9})>0,0),0))&IF(AND(IFERROR(MATCH(TRUE,COUNTIFS(Catálogo!$J$2:$J$648,"*"&$A6&"*",Catálogo!$I$2:$I$648,"<>ausente",Catálogo!$M$2:$M$648,"parcial",Catálogo!$L$2:$L$648,"*area*",Catálogo!$L$2:$L$648,"*sexo*",Catálogo!$Q$2:$Q$648,{1,2,3,4,5,6,7,8,9})>0,0),0)>0,IFERROR(MATCH(TRUE,COUNTIFS(Catálogo!$J$2:$J$648,"*"&$A6&"*",Catálogo!$I$2:$I$648,"<>ausente",Catálogo!$M$2:$M$648,"parcial",Catálogo!$L$2:$L$648,"*area*",Catálogo!$L$2:$L$648,"*sexo*",Catálogo!$Q$2:$Q$648,{1,2,3,4,5,6,7,8,9})>0,0),0)<IFERROR(MATCH(TRUE,COUNTIFS(Catálogo!$J$2:$J$648,"*"&$A6&"*",Catálogo!$I$2:$I$648,"<>ausente",Catálogo!$M$2:$M$648,"completa",Catálogo!$L$2:$L$648,"*area*",Catálogo!$L$2:$L$648,"*sexo*",Catálogo!$Q$2:$Q$648,{1,2,3,4,5,6,7,8,9})>0,0),0)),"; "&LOWER(INDEX(Niveles!$C$2:$C$10,IFERROR(MATCH(TRUE,COUNTIFS(Catálogo!$J$2:$J$648,"*"&$A6&"*",Catálogo!$I$2:$I$648,"<>ausente",Catálogo!$M$2:$M$648,"parcial",Catálogo!$L$2:$L$648,"*area*",Catálogo!$L$2:$L$648,"*sexo*",Catálogo!$Q$2:$Q$648,{1,2,3,4,5,6,7,8,9})>0,0),0)))&" (parcial)",""),IF(IFERROR(MATCH(TRUE,COUNTIFS(Catálogo!$J$2:$J$648,"*"&$A6&"*",Catálogo!$I$2:$I$648,"<>ausente",Catálogo!$M$2:$M$648,"parcial",Catálogo!$L$2:$L$648,"*area*",Catálogo!$L$2:$L$648,"*sexo*",Catálogo!$Q$2:$Q$648,{1,2,3,4,5,6,7,8,9})>0,0),0)>0,INDEX(Niveles!$C$2:$C$10,IFERROR(MATCH(TRUE,COUNTIFS(Catálogo!$J$2:$J$648,"*"&$A6&"*",Catálogo!$I$2:$I$648,"<>ausente",Catálogo!$M$2:$M$648,"parcial",Catálogo!$L$2:$L$648,"*area*",Catálogo!$L$2:$L$648,"*sexo*",Catálogo!$Q$2:$Q$648,{1,2,3,4,5,6,7,8,9})>0,0),0))&" (parcial)","—")) -> — | S6: =IF(COUNTIFS(Cifras!$A$2:$A$399,$A6,Cifras!$F$2:$F$399,"Sí",Cifras!$G$2:$G$399,"Sí",Cifras!$D$2:$D$399,"distrito")>0,"Distrito",IF(COUNTIFS(Cifras!$A$2:$A$399,$A6,Cifras!$F$2:$F$399,"Sí",Cifras!$G$2:$G$399,"Sí",Cifras!$D$2:$D$399,"comuna")>0,"Comuna",IF(COUNTIFS(Cifras!$A$2:$A$399,$A6,Cifras!$F$2:$F$399,"Sí",Cifras!$G$2:$G$399,"Sí",Cifras!$D$2:$D$399,"partido")>0,"Partido",IF(COUNTIFS(Cifras!$A$2:$A$399,$A6,Cifras!$F$2:$F$399,"Sí",Cifras!$G$2:$G$399,"Sí",Cifras!$D$2:$D$399,"departamento")>0,"Departamento",IF(COUNTIFS(Cifras!$A$2:$A$399,$A6,Cifras!$F$2:$F$399,"Sí",Cifras!$G$2:$G$399,"Sí",Cifras!$D$2:$D$399,"provincia")>0,"Provincia",IF(COUNTIFS(Cifras!$A$2:$A$399,$A6,Cifras!$F$2:$F$399,"Sí",Cifras!$G$2:$G$399,"Sí",Cifras!$D$2:$D$399,"region")>0,"Región",IF(COUNTIFS(Cifras!$A$2:$A$399,$A6,Cifras!$F$2:$F$399,"Sí",Cifras!$G$2:$G$399,"Sí",Cifras!$D$2:$D$399,"pais")>0,"País","—"))))))) -> — | T6: =IF(IFERROR(MATCH(TRUE,COUNTIFS(Catálogo!$J$2:$J$648,"*"&$A6&"*",Catálogo!$I$2:$I$648,"<>ausente",Catálogo!$M$2:$M$648,"completa",Catálogo!$L$2:$L$648,"*sexo*",Catálogo!$L$2:$L$648,"*edad*",Catálogo!$Q$2:$Q$648,{1,2,3,4,5,6,7,8,9})>0,0),0)>0,INDEX(Niveles!$C$2:$C$10,IFERROR(MATCH(TRUE,COUNTIFS(Catálogo!$J$2:$J$648,"*"&$A6&"*",Catálogo!$I$2:$I$648,"<>ausente",Catálogo!$M$2:$M$648,"completa",Catálogo!$L$2:$L$648,"*sexo*",Catálogo!$L$2:$L$648,"*edad*",Catálogo!$Q$2:$Q$648,{1,2,3,4,5,6,7,8,9})>0,0),0))&IF(AND(IFERROR(MATCH(TRUE,COUNTIFS(Catálogo!$J$2:$J$648,"*"&$A6&"*",Catálogo!$I$2:$I$648,"<>ausente",Catálogo!$M$2:$M$648,"parcial",Catálogo!$L$2:$L$648,"*sexo*",Catálogo!$L$2:$L$648,"*edad*",Catálogo!$Q$2:$Q$648,{1,2,3,4,5,6,7,8,9})>0,0),0)>0,IFERROR(MATCH(TRUE,COUNTIFS(Catálogo!$J$2:$J$648,"*"&$A6&"*",Catálogo!$I$2:$I$648,"<>ausente",Catálogo!$M$2:$M$648,"parcial",Catálogo!$L$2:$L$648,"*sexo*",Catálogo!$L$2:$L$648,"*edad*",Catálogo!$Q$2:$Q$648,{1,2,3,4,5,6,7,8,9})>0,0),0)<IFERROR(MATCH(TRUE,COUNTIFS(Catálogo!$J$2:$J$648,"*"&$A6&"*",Catálogo!$I$2:$I$648,"<>ausente",Catálogo!$M$2:$M$648,"completa",Catálogo!$L$2:$L$648,"*sexo*",Catálogo!$L$2:$L$648,"*edad*",Catálogo!$Q$2:$Q$648,{1,2,3,4,5,6,7,8,9})>0,0),0)),"; "&LOWER(INDEX(Niveles!$C$2:$C$10,IFERROR(MATCH(TRUE,COUNTIFS(Catálogo!$J$2:$J$648,"*"&$A6&"*",Catálogo!$I$2:$I$648,"<>ausente",Catálogo!$M$2:$M$648,"parcial",Catálogo!$L$2:$L$648,"*sexo*",Catálogo!$L$2:$L$648,"*edad*",Catálogo!$Q$2:$Q$648,{1,2,3,4,5,6,7,8,9})>0,0),0)))&" (parcial)",""),IF(IFERROR(MATCH(TRUE,COUNTIFS(Catálogo!$J$2:$J$648,"*"&$A6&"*",Catálogo!$I$2:$I$648,"<>ausente",Catálogo!$M$2:$M$648,"parcial",Catálogo!$L$2:$L$648,"*sexo*",Catálogo!$L$2:$L$648,"*edad*",Catálogo!$Q$2:$Q$648,{1,2,3,4,5,6,7,8,9})>0,0),0)>0,INDEX(Niveles!$C$2:$C$10,IFERROR(MATCH(TRUE,COUNTIFS(Catálogo!$J$2:$J$648,"*"&$A6&"*",Catálogo!$I$2:$I$648,"<>ausente",Catálogo!$M$2:$M$648,"parcial",Catálogo!$L$2:$L$648,"*sexo*",Catálogo!$L$2:$L$648,"*edad*",Catálogo!$Q$2:$Q$648,{1,2,3,4,5,6,7,8,9})>0,0),0))&" (parcial)","—")) -> — | U6: =SUMIFS(Cifras!$J$2:$J$399,Cifras!$A$2:$A$399,$A6) -> 2 | V6: Parcial | W6: Nada más en el PDF para el núcleo: no trae edad ni área. Opcional: subdelegaciones de Santiago (PDF 93). | X6: Departamento × sexo × estado (solteros/casados) desde la propia publicación (arts. 34–42), validado con los sinópticos de 1865 y 1875 (salvo Cauquenes, +2). Sin edad en la publicación.
A7: 1843 | B7: — | D7: =COUNTIFS(Catálogo!$B$2:$B$648,$A7) -> 0 | E7: =COUNTIFS(Catálogo!$B$2:$B$648,$A7,Catálogo!$F$2:$F$648,"cuadro") -> 0 | F7: =COUNTIFS(Catálogo!$B$2:$B$648,$A7,Catálogo!$F$2:$F$648,"bloque") -> 0 | G7: =COUNTIFS(Catálogo!$B$2:$B$648,$A7,Catálogo!$F$2:$F$648,"texto") -> 0 | H7: =COUNTIFS(Catálogo!$B$2:$B$648,$A7,Catálogo!$I$2:$I$648,"verificada") -> 0 | I7: =COUNTIFS(Catálogo!$B$2:$B$648,$A7,Catálogo!$I$2:$I$648,"estimada") -> 0 | J7: =COUNTIFS(Catálogo!$B$2:$B$648,$A7,Catálogo!$I$2:$I$648,"desconocida")+COUNTIFS(Catálogo!$B$2:$B$648,$A7,Catálogo!$I$2:$I$648,"ausente") -> 0 | K7: =COUNTIFS(Catálogo!$B$2:$B$648,$A7,Catálogo!$O$2:$O$648,"transcrito") -> 0 | L7: =SUMIFS(Cifras!$H$2:$H$399,Cifras!$A$2:$A$399,$A7) -> 137 | M7: =IF(COUNTIFS(Cifras!$A$2:$A$399,$A7,Cifras!$D$2:$D$399,"distrito")>0,"Distrito",IF(COUNTIFS(Cifras!$A$2:$A$399,$A7,Cifras!$D$2:$D$399,"comuna")>0,"Comuna",IF(COUNTIFS(Cifras!$A$2:$A$399,$A7,Cifras!$D$2:$D$399,"partido")>0,"Partido",IF(COUNTIFS(Cifras!$A$2:$A$399,$A7,Cifras!$D$2:$D$399,"departamento")>0,"Departamento",IF(COUNTIFS(Cifras!$A$2:$A$399,$A7,Cifras!$D$2:$D$399,"provincia")>0,"Provincia",IF(COUNTIFS(Cifras!$A$2:$A$399,$A7,Cifras!$D$2:$D$399,"region")>0,"Región",IF(COUNTIFS(Cifras!$A$2:$A$399,$A7,Cifras!$D$2:$D$399,"pais")>0,"País","—"))))))) -> Departamento | N7: =IF(IFERROR(MATCH(TRUE,COUNTIFS(Catálogo!$J$2:$J$648,"*"&$A7&"*",Catálogo!$I$2:$I$648,"<>ausente",Catálogo!$M$2:$M$648,"completa",Catálogo!$Q$2:$Q$648,{1,2,3,4,5,6,7,8,9})>0,0),0)>0,INDEX(Niveles!$C$2:$C$10,IFERROR(MATCH(TRUE,COUNTIFS(Catálogo!$J$2:$J$648,"*"&$A7&"*",Catálogo!$I$2:$I$648,"<>ausente",Catálogo!$M$2:$M$648,"completa",Catálogo!$Q$2:$Q$648,{1,2,3,4,5,6,7,8,9})>0,0),0))&IF(AND(IFERROR(MATCH(TRUE,COUNTIFS(Catálogo!$J$2:$J$648,"*"&$A7&"*",Catálogo!$I$2:$I$648,"<>ausente",Catálogo!$M$2:$M$648,"parcial",Catálogo!$Q$2:$Q$648,{1,2,3,4,5,6,7,8,9})>0,0),0)>0,IFERROR(MATCH(TRUE,COUNTIFS(Catálogo!$J$2:$J$648,"*"&$A7&"*",Catálogo!$I$2:$I$648,"<>ausente",Catálogo!$M$2:$M$648,"parcial",Catálogo!$Q$2:$Q$648,{1,2,3,4,5,6,7,8,9})>0,0),0)<IFERROR(MATCH(TRUE,COUNTIFS(Catálogo!$J$2:$J$648,"*"&$A7&"*",Catálogo!$I$2:$I$648,"<>ausente",Catálogo!$M$2:$M$648,"completa",Catálogo!$Q$2:$Q$648,{1,2,3,4,5,6,7,8,9})>0,0),0)),"; "&LOWER(INDEX(Niveles!$C$2:$C$10,IFERROR(MATCH(TRUE,COUNTIFS(Catálogo!$J$2:$J$648,"*"&$A7&"*",Catálogo!$I$2:$I$648,"<>ausente",Catálogo!$M$2:$M$648,"parcial",Catálogo!$Q$2:$Q$648,{1,2,3,4,5,6,7,8,9})>0,0),0)))&" (parcial)",""),IF(IFERROR(MATCH(TRUE,COUNTIFS(Catálogo!$J$2:$J$648,"*"&$A7&"*",Catálogo!$I$2:$I$648,"<>ausente",Catálogo!$M$2:$M$648,"parcial",Catálogo!$Q$2:$Q$648,{1,2,3,4,5,6,7,8,9})>0,0),0)>0,INDEX(Niveles!$C$2:$C$10,IFERROR(MATCH(TRUE,COUNTIFS(Catálogo!$J$2:$J$648,"*"&$A7&"*",Catálogo!$I$2:$I$648,"<>ausente",Catálogo!$M$2:$M$648,"parcial",Catálogo!$Q$2:$Q$648,{1,2,3,4,5,6,7,8,9})>0,0),0))&" (parcial)","—")) -> Departamento | O7: =IF(COUNTIFS(Cifras!$A$2:$A$399,$A7,Cifras!$E$2:$E$399,"Sí",Cifras!$D$2:$D$399,"distrito")>0,"Distrito",IF(COUNTIFS(Cifras!$A$2:$A$399,$A7,Cifras!$E$2:$E$399,"Sí",Cifras!$D$2:$D$399,"comuna")>0,"Comuna",IF(COUNTIFS(Cifras!$A$2:$A$399,$A7,Cifras!$E$2:$E$399,"Sí",Cifras!$D$2:$D$399,"partido")>0,"Partido",IF(COUNTIFS(Cifras!$A$2:$A$399,$A7,Cifras!$E$2:$E$399,"Sí",Cifras!$D$2:$D$399,"departamento")>0,"Departamento",IF(COUNTIFS(Cifras!$A$2:$A$399,$A7,Cifras!$E$2:$E$399,"Sí",Cifras!$D$2:$D$399,"provincia")>0,"Provincia",IF(COUNTIFS(Cifras!$A$2:$A$399,$A7,Cifras!$E$2:$E$399,"Sí",Cifras!$D$2:$D$399,"region")>0,"Región",IF(COUNTIFS(Cifras!$A$2:$A$399,$A7,Cifras!$E$2:$E$399,"Sí",Cifras!$D$2:$D$399,"pais")>0,"País","—"))))))) -> — | P7: =IF(IFERROR(MATCH(TRUE,COUNTIFS(Catálogo!$J$2:$J$648,"*"&$A7&"*",Catálogo!$I$2:$I$648,"<>ausente",Catálogo!$M$2:$M$648,"completa",Catálogo!$L$2:$L$648,"*area*",Catálogo!$Q$2:$Q$648,{1,2,3,4,5,6,7,8,9})>0,0),0)>0,INDEX(Niveles!$C$2:$C$10,IFERROR(MATCH(TRUE,COUNTIFS(Catálogo!$J$2:$J$648,"*"&$A7&"*",Catálogo!$I$2:$I$648,"<>ausente",Catálogo!$M$2:$M$648,"completa",Catálogo!$L$2:$L$648,"*area*",Catálogo!$Q$2:$Q$648,{1,2,3,4,5,6,7,8,9})>0,0),0))&IF(AND(IFERROR(MATCH(TRUE,COUNTIFS(Catálogo!$J$2:$J$648,"*"&$A7&"*",Catálogo!$I$2:$I$648,"<>ausente",Catálogo!$M$2:$M$648,"parcial",Catálogo!$L$2:$L$648,"*area*",Catálogo!$Q$2:$Q$648,{1,2,3,4,5,6,7,8,9})>0,0),0)>0,IFERROR(MATCH(TRUE,COUNTIFS(Catálogo!$J$2:$J$648,"*"&$A7&"*",Catálogo!$I$2:$I$648,"<>ausente",Catálogo!$M$2:$M$648,"parcial",Catálogo!$L$2:$L$648,"*area*",Catálogo!$Q$2:$Q$648,{1,2,3,4,5,6,7,8,9})>0,0),0)<IFERROR(MATCH(TRUE,COUNTIFS(Catálogo!$J$2:$J$648,"*"&$A7&"*",Catálogo!$I$2:$I$648,"<>ausente",Catálogo!$M$2:$M$648,"completa",Catálogo!$L$2:$L$648,"*area*",Catálogo!$Q$2:$Q$648,{1,2,3,4,5,6,7,8,9})>0,0),0)),"; "&LOWER(INDEX(Niveles!$C$2:$C$10,IFERROR(MATCH(TRUE,COUNTIFS(Catálogo!$J$2:$J$648,"*"&$A7&"*",Catálogo!$I$2:$I$648,"<>ausente",Catálogo!$M$2:$M$648,"parcial",Catálogo!$L$2:$L$648,"*area*",Catálogo!$Q$2:$Q$648,{1,2,3,4,5,6,7,8,9})>0,0),0)))&" (parcial)",""),IF(IFERROR(MATCH(TRUE,COUNTIFS(Catálogo!$J$2:$J$648,"*"&$A7&"*",Catálogo!$I$2:$I$648,"<>ausente",Catálogo!$M$2:$M$648,"parcial",Catálogo!$L$2:$L$648,"*area*",Catálogo!$Q$2:$Q$648,{1,2,3,4,5,6,7,8,9})>0,0),0)>0,INDEX(Niveles!$C$2:$C$10,IFERROR(MATCH(TRUE,COUNTIFS(Catálogo!$J$2:$J$648,"*"&$A7&"*",Catálogo!$I$2:$I$648,"<>ausente",Catálogo!$M$2:$M$648,"parcial",Catálogo!$L$2:$L$648,"*area*",Catálogo!$Q$2:$Q$648,{1,2,3,4,5,6,7,8,9})>0,0),0))&" (parcial)","—")) -> — | Q7: =IF(COUNTIFS(Cifras!$A$2:$A$399,$A7,Cifras!$E$2:$E$399,"Sí",Cifras!$F$2:$F$399,"Sí",Cifras!$D$2:$D$399,"distrito")>0,"Distrito",IF(COUNTIFS(Cifras!$A$2:$A$399,$A7,Cifras!$E$2:$E$399,"Sí",Cifras!$F$2:$F$399,"Sí",Cifras!$D$2:$D$399,"comuna")>0,"Comuna",IF(COUNTIFS(Cifras!$A$2:$A$399,$A7,Cifras!$E$2:$E$399,"Sí",Cifras!$F$2:$F$399,"Sí",Cifras!$D$2:$D$399,"partido")>0,"Partido",IF(COUNTIFS(Cifras!$A$2:$A$399,$A7,Cifras!$E$2:$E$399,"Sí",Cifras!$F$2:$F$399,"Sí",Cifras!$D$2:$D$399,"departamento")>0,"Departamento",IF(COUNTIFS(Cifras!$A$2:$A$399,$A7,Cifras!$E$2:$E$399,"Sí",Cifras!$F$2:$F$399,"Sí",Cifras!$D$2:$D$399,"provincia")>0,"Provincia",IF(COUNTIFS(Cifras!$A$2:$A$399,$A7,Cifras!$E$2:$E$399,"Sí",Cifras!$F$2:$F$399,"Sí",Cifras!$D$2:$D$399,"region")>0,"Región",IF(COUNTIFS(Cifras!$A$2:$A$399,$A7,Cifras!$E$2:$E$399,"Sí",Cifras!$F$2:$F$399,"Sí",Cifras!$D$2:$D$399,"pais")>0,"País","—"))))))) -> — | R7: =IF(IFERROR(MATCH(TRUE,COUNTIFS(Catálogo!$J$2:$J$648,"*"&$A7&"*",Catálogo!$I$2:$I$648,"<>ausente",Catálogo!$M$2:$M$648,"completa",Catálogo!$L$2:$L$648,"*area*",Catálogo!$L$2:$L$648,"*sexo*",Catálogo!$Q$2:$Q$648,{1,2,3,4,5,6,7,8,9})>0,0),0)>0,INDEX(Niveles!$C$2:$C$10,IFERROR(MATCH(TRUE,COUNTIFS(Catálogo!$J$2:$J$648,"*"&$A7&"*",Catálogo!$I$2:$I$648,"<>ausente",Catálogo!$M$2:$M$648,"completa",Catálogo!$L$2:$L$648,"*area*",Catálogo!$L$2:$L$648,"*sexo*",Catálogo!$Q$2:$Q$648,{1,2,3,4,5,6,7,8,9})>0,0),0))&IF(AND(IFERROR(MATCH(TRUE,COUNTIFS(Catálogo!$J$2:$J$648,"*"&$A7&"*",Catálogo!$I$2:$I$648,"<>ausente",Catálogo!$M$2:$M$648,"parcial",Catálogo!$L$2:$L$648,"*area*",Catálogo!$L$2:$L$648,"*sexo*",Catálogo!$Q$2:$Q$648,{1,2,3,4,5,6,7,8,9})>0,0),0)>0,IFERROR(MATCH(TRUE,COUNTIFS(Catálogo!$J$2:$J$648,"*"&$A7&"*",Catálogo!$I$2:$I$648,"<>ausente",Catálogo!$M$2:$M$648,"parcial",Catálogo!$L$2:$L$648,"*area*",Catálogo!$L$2:$L$648,"*sexo*",Catálogo!$Q$2:$Q$648,{1,2,3,4,5,6,7,8,9})>0,0),0)<IFERROR(MATCH(TRUE,COUNTIFS(Catálogo!$J$2:$J$648,"*"&$A7&"*",Catálogo!$I$2:$I$648,"<>ausente",Catálogo!$M$2:$M$648,"completa",Catálogo!$L$2:$L$648,"*area*",Catálogo!$L$2:$L$648,"*sexo*",Catálogo!$Q$2:$Q$648,{1,2,3,4,5,6,7,8,9})>0,0),0)),"; "&LOWER(INDEX(Niveles!$C$2:$C$10,IFERROR(MATCH(TRUE,COUNTIFS(Catálogo!$J$2:$J$648,"*"&$A7&"*",Catálogo!$I$2:$I$648,"<>ausente",Catálogo!$M$2:$M$648,"parcial",Catálogo!$L$2:$L$648,"*area*",Catálogo!$L$2:$L$648,"*sexo*",Catálogo!$Q$2:$Q$648,{1,2,3,4,5,6,7,8,9})>0,0),0)))&" (parcial)",""),IF(IFERROR(MATCH(TRUE,COUNTIFS(Catálogo!$J$2:$J$648,"*"&$A7&"*",Catálogo!$I$2:$I$648,"<>ausente",Catálogo!$M$2:$M$648,"parcial",Catálogo!$L$2:$L$648,"*area*",Catálogo!$L$2:$L$648,"*sexo*",Catálogo!$Q$2:$Q$648,{1,2,3,4,5,6,7,8,9})>0,0),0)>0,INDEX(Niveles!$C$2:$C$10,IFERROR(MATCH(TRUE,COUNTIFS(Catálogo!$J$2:$J$648,"*"&$A7&"*",Catálogo!$I$2:$I$648,"<>ausente",Catálogo!$M$2:$M$648,"parcial",Catálogo!$L$2:$L$648,"*area*",Catálogo!$L$2:$L$648,"*sexo*",Catálogo!$Q$2:$Q$648,{1,2,3,4,5,6,7,8,9})>0,0),0))&" (parcial)","—")) -> — | S7: =IF(COUNTIFS(Cifras!$A$2:$A$399,$A7,Cifras!$F$2:$F$399,"Sí",Cifras!$G$2:$G$399,"Sí",Cifras!$D$2:$D$399,"distrito")>0,"Distrito",IF(COUNTIFS(Cifras!$A$2:$A$399,$A7,Cifras!$F$2:$F$399,"Sí",Cifras!$G$2:$G$399,"Sí",Cifras!$D$2:$D$399,"comuna")>0,"Comuna",IF(COUNTIFS(Cifras!$A$2:$A$399,$A7,Cifras!$F$2:$F$399,"Sí",Cifras!$G$2:$G$399,"Sí",Cifras!$D$2:$D$399,"partido")>0,"Partido",IF(COUNTIFS(Cifras!$A$2:$A$399,$A7,Cifras!$F$2:$F$399,"Sí",Cifras!$G$2:$G$399,"Sí",Cifras!$D$2:$D$399,"departamento")>0,"Departamento",IF(COUNTIFS(Cifras!$A$2:$A$399,$A7,Cifras!$F$2:$F$399,"Sí",Cifras!$G$2:$G$399,"Sí",Cifras!$D$2:$D$399,"provincia")>0,"Provincia",IF(COUNTIFS(Cifras!$A$2:$A$399,$A7,Cifras!$F$2:$F$399,"Sí",Cifras!$G$2:$G$399,"Sí",Cifras!$D$2:$D$399,"region")>0,"Región",IF(COUNTIFS(Cifras!$A$2:$A$399,$A7,Cifras!$F$2:$F$399,"Sí",Cifras!$G$2:$G$399,"Sí",Cifras!$D$2:$D$399,"pais")>0,"País","—"))))))) -> — | T7: =IF(IFERROR(MATCH(TRUE,COUNTIFS(Catálogo!$J$2:$J$648,"*"&$A7&"*",Catálogo!$I$2:$I$648,"<>ausente",Catálogo!$M$2:$M$648,"completa",Catálogo!$L$2:$L$648,"*sexo*",Catálogo!$L$2:$L$648,"*edad*",Catálogo!$Q$2:$Q$648,{1,2,3,4,5,6,7,8,9})>0,0),0)>0,INDEX(Niveles!$C$2:$C$10,IFERROR(MATCH(TRUE,COUNTIFS(Catálogo!$J$2:$J$648,"*"&$A7&"*",Catálogo!$I$2:$I$648,"<>ausente",Catálogo!$M$2:$M$648,"completa",Catálogo!$L$2:$L$648,"*sexo*",Catálogo!$L$2:$L$648,"*edad*",Catálogo!$Q$2:$Q$648,{1,2,3,4,5,6,7,8,9})>0,0),0))&IF(AND(IFERROR(MATCH(TRUE,COUNTIFS(Catálogo!$J$2:$J$648,"*"&$A7&"*",Catálogo!$I$2:$I$648,"<>ausente",Catálogo!$M$2:$M$648,"parcial",Catálogo!$L$2:$L$648,"*sexo*",Catálogo!$L$2:$L$648,"*edad*",Catálogo!$Q$2:$Q$648,{1,2,3,4,5,6,7,8,9})>0,0),0)>0,IFERROR(MATCH(TRUE,COUNTIFS(Catálogo!$J$2:$J$648,"*"&$A7&"*",Catálogo!$I$2:$I$648,"<>ausente",Catálogo!$M$2:$M$648,"parcial",Catálogo!$L$2:$L$648,"*sexo*",Catálogo!$L$2:$L$648,"*edad*",Catálogo!$Q$2:$Q$648,{1,2,3,4,5,6,7,8,9})>0,0),0)<IFERROR(MATCH(TRUE,COUNTIFS(Catálogo!$J$2:$J$648,"*"&$A7&"*",Catálogo!$I$2:$I$648,"<>ausente",Catálogo!$M$2:$M$648,"completa",Catálogo!$L$2:$L$648,"*sexo*",Catálogo!$L$2:$L$648,"*edad*",Catálogo!$Q$2:$Q$648,{1,2,3,4,5,6,7,8,9})>0,0),0)),"; "&LOWER(INDEX(Niveles!$C$2:$C$10,IFERROR(MATCH(TRUE,COUNTIFS(Catálogo!$J$2:$J$648,"*"&$A7&"*",Catálogo!$I$2:$I$648,"<>ausente",Catálogo!$M$2:$M$648,"parcial",Catálogo!$L$2:$L$648,"*sexo*",Catálogo!$L$2:$L$648,"*edad*",Catálogo!$Q$2:$Q$648,{1,2,3,4,5,6,7,8,9})>0,0),0)))&" (parcial)",""),IF(IFERROR(MATCH(TRUE,COUNTIFS(Catálogo!$J$2:$J$648,"*"&$A7&"*",Catálogo!$I$2:$I$648,"<>ausente",Catálogo!$M$2:$M$648,"parcial",Catálogo!$L$2:$L$648,"*sexo*",Catálogo!$L$2:$L$648,"*edad*",Catálogo!$Q$2:$Q$648,{1,2,3,4,5,6,7,8,9})>0,0),0)>0,INDEX(Niveles!$C$2:$C$10,IFERROR(MATCH(TRUE,COUNTIFS(Catálogo!$J$2:$J$648,"*"&$A7&"*",Catálogo!$I$2:$I$648,"<>ausente",Catálogo!$M$2:$M$648,"parcial",Catálogo!$L$2:$L$648,"*sexo*",Catálogo!$L$2:$L$648,"*edad*",Catálogo!$Q$2:$Q$648,{1,2,3,4,5,6,7,8,9})>0,0),0))&" (parcial)","—")) -> — | U7: =SUMIFS(Cifras!$J$2:$J$399,Cifras!$A$2:$A$399,$A7) -> 0 | V7: Sin publicación | W7: Transcribir la provincia del Maule (departamento y subdelegación × sexo × edad; copia de Memoria Chilena mc_1843_maule, PDF 72–98). Revisar la población por subdelegación del Repertorio nacional de 1850 (mc_1843_repertorio). | X7: Solo se publicó la provincia del Maule (Memoria Chilena), sin transcribir. Departamento y provincia (totales) desde los sinópticos de 1865 y 1875, que coinciden entre sí.
A8: 1854 | B8: — | D8: =COUNTIFS(Catálogo!$B$2:$B$648,$A8) -> 0 | E8: =COUNTIFS(Catálogo!$B$2:$B$648,$A8,Catálogo!$F$2:$F$648,"cuadro") -> 0 | F8: =COUNTIFS(Catálogo!$B$2:$B$648,$A8,Catálogo!$F$2:$F$648,"bloque") -> 0 | G8: =COUNTIFS(Catálogo!$B$2:$B$648,$A8,Catálogo!$F$2:$F$648,"texto") -> 0 | H8: =COUNTIFS(Catálogo!$B$2:$B$648,$A8,Catálogo!$I$2:$I$648,"verificada") -> 0 | I8: =COUNTIFS(Catálogo!$B$2:$B$648,$A8,Catálogo!$I$2:$I$648,"estimada") -> 0 | J8: =COUNTIFS(Catálogo!$B$2:$B$648,$A8,Catálogo!$I$2:$I$648,"desconocida")+COUNTIFS(Catálogo!$B$2:$B$648,$A8,Catálogo!$I$2:$I$648,"ausente") -> 0 | K8: =COUNTIFS(Catálogo!$B$2:$B$648,$A8,Catálogo!$O$2:$O$648,"transcrito") -> 0 | L8: =SUMIFS(Cifras!$H$2:$H$399,Cifras!$A$2:$A$399,$A8) -> 147 | M8: =IF(COUNTIFS(Cifras!$A$2:$A$399,$A8,Cifras!$D$2:$D$399,"distrito")>0,"Distrito",IF(COUNTIFS(Cifras!$A$2:$A$399,$A8,Cifras!$D$2:$D$399,"comuna")>0,"Comuna",IF(COUNTIFS(Cifras!$A$2:$A$399,$A8,Cifras!$D$2:$D$399,"partido")>0,"Partido",IF(COUNTIFS(Cifras!$A$2:$A$399,$A8,Cifras!$D$2:$D$399,"departamento")>0,"Departamento",IF(COUNTIFS(Cifras!$A$2:$A$399,$A8,Cifras!$D$2:$D$399,"provincia")>0,"Provincia",IF(COUNTIFS(Cifras!$A$2:$A$399,$A8,Cifras!$D$2:$D$399,"region")>0,"Región",IF(COUNTIFS(Cifras!$A$2:$A$399,$A8,Cifras!$D$2:$D$399,"pais")>0,"País","—"))))))) -> Departamento | N8: =IF(IFERROR(MATCH(TRUE,COUNTIFS(Catálogo!$J$2:$J$648,"*"&$A8&"*",Catálogo!$I$2:$I$648,"<>ausente",Catálogo!$M$2:$M$648,"completa",Catálogo!$Q$2:$Q$648,{1,2,3,4,5,6,7,8,9})>0,0),0)>0,INDEX(Niveles!$C$2:$C$10,IFERROR(MATCH(TRUE,COUNTIFS(Catálogo!$J$2:$J$648,"*"&$A8&"*",Catálogo!$I$2:$I$648,"<>ausente",Catálogo!$M$2:$M$648,"completa",Catálogo!$Q$2:$Q$648,{1,2,3,4,5,6,7,8,9})>0,0),0))&IF(AND(IFERROR(MATCH(TRUE,COUNTIFS(Catálogo!$J$2:$J$648,"*"&$A8&"*",Catálogo!$I$2:$I$648,"<>ausente",Catálogo!$M$2:$M$648,"parcial",Catálogo!$Q$2:$Q$648,{1,2,3,4,5,6,7,8,9})>0,0),0)>0,IFERROR(MATCH(TRUE,COUNTIFS(Catálogo!$J$2:$J$648,"*"&$A8&"*",Catálogo!$I$2:$I$648,"<>ausente",Catálogo!$M$2:$M$648,"parcial",Catálogo!$Q$2:$Q$648,{1,2,3,4,5,6,7,8,9})>0,0),0)<IFERROR(MATCH(TRUE,COUNTIFS(Catálogo!$J$2:$J$648,"*"&$A8&"*",Catálogo!$I$2:$I$648,"<>ausente",Catálogo!$M$2:$M$648,"completa",Catálogo!$Q$2:$Q$648,{1,2,3,4,5,6,7,8,9})>0,0),0)),"; "&LOWER(INDEX(Niveles!$C$2:$C$10,IFERROR(MATCH(TRUE,COUNTIFS(Catálogo!$J$2:$J$648,"*"&$A8&"*",Catálogo!$I$2:$I$648,"<>ausente",Catálogo!$M$2:$M$648,"parcial",Catálogo!$Q$2:$Q$648,{1,2,3,4,5,6,7,8,9})>0,0),0)))&" (parcial)",""),IF(IFERROR(MATCH(TRUE,COUNTIFS(Catálogo!$J$2:$J$648,"*"&$A8&"*",Catálogo!$I$2:$I$648,"<>ausente",Catálogo!$M$2:$M$648,"parcial",Catálogo!$Q$2:$Q$648,{1,2,3,4,5,6,7,8,9})>0,0),0)>0,INDEX(Niveles!$C$2:$C$10,IFERROR(MATCH(TRUE,COUNTIFS(Catálogo!$J$2:$J$648,"*"&$A8&"*",Catálogo!$I$2:$I$648,"<>ausente",Catálogo!$M$2:$M$648,"parcial",Catálogo!$Q$2:$Q$648,{1,2,3,4,5,6,7,8,9})>0,0),0))&" (parcial)","—")) -> Departamento | O8: =IF(COUNTIFS(Cifras!$A$2:$A$399,$A8,Cifras!$E$2:$E$399,"Sí",Cifras!$D$2:$D$399,"distrito")>0,"Distrito",IF(COUNTIFS(Cifras!$A$2:$A$399,$A8,Cifras!$E$2:$E$399,"Sí",Cifras!$D$2:$D$399,"comuna")>0,"Comuna",IF(COUNTIFS(Cifras!$A$2:$A$399,$A8,Cifras!$E$2:$E$399,"Sí",Cifras!$D$2:$D$399,"partido")>0,"Partido",IF(COUNTIFS(Cifras!$A$2:$A$399,$A8,Cifras!$E$2:$E$399,"Sí",Cifras!$D$2:$D$399,"departamento")>0,"Departamento",IF(COUNTIFS(Cifras!$A$2:$A$399,$A8,Cifras!$E$2:$E$399,"Sí",Cifras!$D$2:$D$399,"provincia")>0,"Provincia",IF(COUNTIFS(Cifras!$A$2:$A$399,$A8,Cifras!$E$2:$E$399,"Sí",Cifras!$D$2:$D$399,"region")>0,"Región",IF(COUNTIFS(Cifras!$A$2:$A$399,$A8,Cifras!$E$2:$E$399,"Sí",Cifras!$D$2:$D$399,"pais")>0,"País","—"))))))) -> — | P8: =IF(IFERROR(MATCH(TRUE,COUNTIFS(Catálogo!$J$2:$J$648,"*"&$A8&"*",Catálogo!$I$2:$I$648,"<>ausente",Catálogo!$M$2:$M$648,"completa",Catálogo!$L$2:$L$648,"*area*",Catálogo!$Q$2:$Q$648,{1,2,3,4,5,6,7,8,9})>0,0),0)>0,INDEX(Niveles!$C$2:$C$10,IFERROR(MATCH(TRUE,COUNTIFS(Catálogo!$J$2:$J$648,"*"&$A8&"*",Catálogo!$I$2:$I$648,"<>ausente",Catálogo!$M$2:$M$648,"completa",Catálogo!$L$2:$L$648,"*area*",Catálogo!$Q$2:$Q$648,{1,2,3,4,5,6,7,8,9})>0,0),0))&IF(AND(IFERROR(MATCH(TRUE,COUNTIFS(Catálogo!$J$2:$J$648,"*"&$A8&"*",Catálogo!$I$2:$I$648,"<>ausente",Catálogo!$M$2:$M$648,"parcial",Catálogo!$L$2:$L$648,"*area*",Catálogo!$Q$2:$Q$648,{1,2,3,4,5,6,7,8,9})>0,0),0)>0,IFERROR(MATCH(TRUE,COUNTIFS(Catálogo!$J$2:$J$648,"*"&$A8&"*",Catálogo!$I$2:$I$648,"<>ausente",Catálogo!$M$2:$M$648,"parcial",Catálogo!$L$2:$L$648,"*area*",Catálogo!$Q$2:$Q$648,{1,2,3,4,5,6,7,8,9})>0,0),0)<IFERROR(MATCH(TRUE,COUNTIFS(Catálogo!$J$2:$J$648,"*"&$A8&"*",Catálogo!$I$2:$I$648,"<>ausente",Catálogo!$M$2:$M$648,"completa",Catálogo!$L$2:$L$648,"*area*",Catálogo!$Q$2:$Q$648,{1,2,3,4,5,6,7,8,9})>0,0),0)),"; "&LOWER(INDEX(Niveles!$C$2:$C$10,IFERROR(MATCH(TRUE,COUNTIFS(Catálogo!$J$2:$J$648,"*"&$A8&"*",Catálogo!$I$2:$I$648,"<>ausente",Catálogo!$M$2:$M$648,"parcial",Catálogo!$L$2:$L$648,"*area*",Catálogo!$Q$2:$Q$648,{1,2,3,4,5,6,7,8,9})>0,0),0)))&" (parcial)",""),IF(IFERROR(MATCH(TRUE,COUNTIFS(Catálogo!$J$2:$J$648,"*"&$A8&"*",Catálogo!$I$2:$I$648,"<>ausente",Catálogo!$M$2:$M$648,"parcial",Catálogo!$L$2:$L$648,"*area*",Catálogo!$Q$2:$Q$648,{1,2,3,4,5,6,7,8,9})>0,0),0)>0,INDEX(Niveles!$C$2:$C$10,IFERROR(MATCH(TRUE,COUNTIFS(Catálogo!$J$2:$J$648,"*"&$A8&"*",Catálogo!$I$2:$I$648,"<>ausente",Catálogo!$M$2:$M$648,"parcial",Catálogo!$L$2:$L$648,"*area*",Catálogo!$Q$2:$Q$648,{1,2,3,4,5,6,7,8,9})>0,0),0))&" (parcial)","—")) -> — | Q8: =IF(COUNTIFS(Cifras!$A$2:$A$399,$A8,Cifras!$E$2:$E$399,"Sí",Cifras!$F$2:$F$399,"Sí",Cifras!$D$2:$D$399,"distrito")>0,"Distrito",IF(COUNTIFS(Cifras!$A$2:$A$399,$A8,Cifras!$E$2:$E$399,"Sí",Cifras!$F$2:$F$399,"Sí",Cifras!$D$2:$D$399,"comuna")>0,"Comuna",IF(COUNTIFS(Cifras!$A$2:$A$399,$A8,Cifras!$E$2:$E$399,"Sí",Cifras!$F$2:$F$399,"Sí",Cifras!$D$2:$D$399,"partido")>0,"Partido",IF(COUNTIFS(Cifras!$A$2:$A$399,$A8,Cifras!$E$2:$E$399,"Sí",Cifras!$F$2:$F$399,"Sí",Cifras!$D$2:$D$399,"departamento")>0,"Departamento",IF(COUNTIFS(Cifras!$A$2:$A$399,$A8,Cifras!$E$2:$E$399,"Sí",Cifras!$F$2:$F$399,"Sí",Cifras!$D$2:$D$399,"provincia")>0,"Provincia",IF(COUNTIFS(Cifras!$A$2:$A$399,$A8,Cifras!$E$2:$E$399,"Sí",Cifras!$F$2:$F$399,"Sí",Cifras!$D$2:$D$399,"region")>0,"Región",IF(COUNTIFS(Cifras!$A$2:$A$399,$A8,Cifras!$E$2:$E$399,"Sí",Cifras!$F$2:$F$399,"Sí",Cifras!$D$2:$D$399,"pais")>0,"País","—"))))))) -> — | R8: =IF(IFERROR(MATCH(TRUE,COUNTIFS(Catálogo!$J$2:$J$648,"*"&$A8&"*",Catálogo!$I$2:$I$648,"<>ausente",Catálogo!$M$2:$M$648,"completa",Catálogo!$L$2:$L$648,"*area*",Catálogo!$L$2:$L$648,"*sexo*",Catálogo!$Q$2:$Q$648,{1,2,3,4,5,6,7,8,9})>0,0),0)>0,INDEX(Niveles!$C$2:$C$10,IFERROR(MATCH(TRUE,COUNTIFS(Catálogo!$J$2:$J$648,"*"&$A8&"*",Catálogo!$I$2:$I$648,"<>ausente",Catálogo!$M$2:$M$648,"completa",Catálogo!$L$2:$L$648,"*area*",Catálogo!$L$2:$L$648,"*sexo*",Catálogo!$Q$2:$Q$648,{1,2,3,4,5,6,7,8,9})>0,0),0))&IF(AND(IFERROR(MATCH(TRUE,COUNTIFS(Catálogo!$J$2:$J$648,"*"&$A8&"*",Catálogo!$I$2:$I$648,"<>ausente",Catálogo!$M$2:$M$648,"parcial",Catálogo!$L$2:$L$648,"*area*",Catálogo!$L$2:$L$648,"*sexo*",Catálogo!$Q$2:$Q$648,{1,2,3,4,5,6,7,8,9})>0,0),0)>0,IFERROR(MATCH(TRUE,COUNTIFS(Catálogo!$J$2:$J$648,"*"&$A8&"*",Catálogo!$I$2:$I$648,"<>ausente",Catálogo!$M$2:$M$648,"parcial",Catálogo!$L$2:$L$648,"*area*",Catálogo!$L$2:$L$648,"*sexo*",Catálogo!$Q$2:$Q$648,{1,2,3,4,5,6,7,8,9})>0,0),0)<IFERROR(MATCH(TRUE,COUNTIFS(Catálogo!$J$2:$J$648,"*"&$A8&"*",Catálogo!$I$2:$I$648,"<>ausente",Catálogo!$M$2:$M$648,"completa",Catálogo!$L$2:$L$648,"*area*",Catálogo!$L$2:$L$648,"*sexo*",Catálogo!$Q$2:$Q$648,{1,2,3,4,5,6,7,8,9})>0,0),0)),"; "&LOWER(INDEX(Niveles!$C$2:$C$10,IFERROR(MATCH(TRUE,COUNTIFS(Catálogo!$J$2:$J$648,"*"&$A8&"*",Catálogo!$I$2:$I$648,"<>ausente",Catálogo!$M$2:$M$648,"parcial",Catálogo!$L$2:$L$648,"*area*",Catálogo!$L$2:$L$648,"*sexo*",Catálogo!$Q$2:$Q$648,{1,2,3,4,5,6,7,8,9})>0,0),0)))&" (parcial)",""),IF(IFERROR(MATCH(TRUE,COUNTIFS(Catálogo!$J$2:$J$648,"*"&$A8&"*",Catálogo!$I$2:$I$648,"<>ausente",Catálogo!$M$2:$M$648,"parcial",Catálogo!$L$2:$L$648,"*area*",Catálogo!$L$2:$L$648,"*sexo*",Catálogo!$Q$2:$Q$648,{1,2,3,4,5,6,7,8,9})>0,0),0)>0,INDEX(Niveles!$C$2:$C$10,IFERROR(MATCH(TRUE,COUNTIFS(Catálogo!$J$2:$J$648,"*"&$A8&"*",Catálogo!$I$2:$I$648,"<>ausente",Catálogo!$M$2:$M$648,"parcial",Catálogo!$L$2:$L$648,"*area*",Catálogo!$L$2:$L$648,"*sexo*",Catálogo!$Q$2:$Q$648,{1,2,3,4,5,6,7,8,9})>0,0),0))&" (parcial)","—")) -> — | S8: =IF(COUNTIFS(Cifras!$A$2:$A$399,$A8,Cifras!$F$2:$F$399,"Sí",Cifras!$G$2:$G$399,"Sí",Cifras!$D$2:$D$399,"distrito")>0,"Distrito",IF(COUNTIFS(Cifras!$A$2:$A$399,$A8,Cifras!$F$2:$F$399,"Sí",Cifras!$G$2:$G$399,"Sí",Cifras!$D$2:$D$399,"comuna")>0,"Comuna",IF(COUNTIFS(Cifras!$A$2:$A$399,$A8,Cifras!$F$2:$F$399,"Sí",Cifras!$G$2:$G$399,"Sí",Cifras!$D$2:$D$399,"partido")>0,"Partido",IF(COUNTIFS(Cifras!$A$2:$A$399,$A8,Cifras!$F$2:$F$399,"Sí",Cifras!$G$2:$G$399,"Sí",Cifras!$D$2:$D$399,"departamento")>0,"Departamento",IF(COUNTIFS(Cifras!$A$2:$A$399,$A8,Cifras!$F$2:$F$399,"Sí",Cifras!$G$2:$G$399,"Sí",Cifras!$D$2:$D$399,"provincia")>0,"Provincia",IF(COUNTIFS(Cifras!$A$2:$A$399,$A8,Cifras!$F$2:$F$399,"Sí",Cifras!$G$2:$G$399,"Sí",Cifras!$D$2:$D$399,"region")>0,"Región",IF(COUNTIFS(Cifras!$A$2:$A$399,$A8,Cifras!$F$2:$F$399,"Sí",Cifras!$G$2:$G$399,"Sí",Cifras!$D$2:$D$399,"pais")>0,"País","—"))))))) -> — | T8: =IF(IFERROR(MATCH(TRUE,COUNTIFS(Catálogo!$J$2:$J$648,"*"&$A8&"*",Catálogo!$I$2:$I$648,"<>ausente",Catálogo!$M$2:$M$648,"completa",Catálogo!$L$2:$L$648,"*sexo*",Catálogo!$L$2:$L$648,"*edad*",Catálogo!$Q$2:$Q$648,{1,2,3,4,5,6,7,8,9})>0,0),0)>0,INDEX(Niveles!$C$2:$C$10,IFERROR(MATCH(TRUE,COUNTIFS(Catálogo!$J$2:$J$648,"*"&$A8&"*",Catálogo!$I$2:$I$648,"<>ausente",Catálogo!$M$2:$M$648,"completa",Catálogo!$L$2:$L$648,"*sexo*",Catálogo!$L$2:$L$648,"*edad*",Catálogo!$Q$2:$Q$648,{1,2,3,4,5,6,7,8,9})>0,0),0))&IF(AND(IFERROR(MATCH(TRUE,COUNTIFS(Catálogo!$J$2:$J$648,"*"&$A8&"*",Catálogo!$I$2:$I$648,"<>ausente",Catálogo!$M$2:$M$648,"parcial",Catálogo!$L$2:$L$648,"*sexo*",Catálogo!$L$2:$L$648,"*edad*",Catálogo!$Q$2:$Q$648,{1,2,3,4,5,6,7,8,9})>0,0),0)>0,IFERROR(MATCH(TRUE,COUNTIFS(Catálogo!$J$2:$J$648,"*"&$A8&"*",Catálogo!$I$2:$I$648,"<>ausente",Catálogo!$M$2:$M$648,"parcial",Catálogo!$L$2:$L$648,"*sexo*",Catálogo!$L$2:$L$648,"*edad*",Catálogo!$Q$2:$Q$648,{1,2,3,4,5,6,7,8,9})>0,0),0)<IFERROR(MATCH(TRUE,COUNTIFS(Catálogo!$J$2:$J$648,"*"&$A8&"*",Catálogo!$I$2:$I$648,"<>ausente",Catálogo!$M$2:$M$648,"completa",Catálogo!$L$2:$L$648,"*sexo*",Catálogo!$L$2:$L$648,"*edad*",Catálogo!$Q$2:$Q$648,{1,2,3,4,5,6,7,8,9})>0,0),0)),"; "&LOWER(INDEX(Niveles!$C$2:$C$10,IFERROR(MATCH(TRUE,COUNTIFS(Catálogo!$J$2:$J$648,"*"&$A8&"*",Catálogo!$I$2:$I$648,"<>ausente",Catálogo!$M$2:$M$648,"parcial",Catálogo!$L$2:$L$648,"*sexo*",Catálogo!$L$2:$L$648,"*edad*",Catálogo!$Q$2:$Q$648,{1,2,3,4,5,6,7,8,9})>0,0),0)))&" (parcial)",""),IF(IFERROR(MATCH(TRUE,COUNTIFS(Catálogo!$J$2:$J$648,"*"&$A8&"*",Catálogo!$I$2:$I$648,"<>ausente",Catálogo!$M$2:$M$648,"parcial",Catálogo!$L$2:$L$648,"*sexo*",Catálogo!$L$2:$L$648,"*edad*",Catálogo!$Q$2:$Q$648,{1,2,3,4,5,6,7,8,9})>0,0),0)>0,INDEX(Niveles!$C$2:$C$10,IFERROR(MATCH(TRUE,COUNTIFS(Catálogo!$J$2:$J$648,"*"&$A8&"*",Catálogo!$I$2:$I$648,"<>ausente",Catálogo!$M$2:$M$648,"parcial",Catálogo!$L$2:$L$648,"*sexo*",Catálogo!$L$2:$L$648,"*edad*",Catálogo!$Q$2:$Q$648,{1,2,3,4,5,6,7,8,9})>0,0),0))&" (parcial)","—")) -> — | U8: =SUMIFS(Cifras!$J$2:$J$399,Cifras!$A$2:$A$399,$A8) -> 0 | V8: Sin publicación | W8: Opcional: contrastar con el resumen general de 1907 (PDF 1222). Buscar un ejemplar digitalizado. | X8: Sin publicación digitalizada. Departamento y provincia (totales) desde los sinópticos de 1865 y 1875, que coinciden entre sí.
